Workbook

Sheet Base
A1: !TABULKA POČÍTÁ S MINIMÁLNĚ S 1 SW A PŮVODNÍ ADRESOU KONČÍCÍ 0 | F1: TATO BARVA = UPRAVIT | I1: MAXIMÁLNÍ POČET PODSÍŤÍ - 56 (lze navýšit) | L1: Lze zadat sítě náhodně, poté je seřadit
A2: Base_IP | C2: Základní zadaná IP
A4: Název/Barva | B4: Počet PC/R | C4: Počet SW | D4: Mezi R? | E4: Adresa Sítě | F4: Maska | G4: Prefix | H4: Gateway | I4: První Switch | J4: Poslední Switch | K4: První použitelná IP | L4: Poslední použitelná IP | M4: Broadcast
A5: Síť 1 | E5: =IF($B5="","",Count!L5) | F5: =IF($B5="","",Count!M5) | G5: =IF($B5="","",_xlfn.CONCAT("/",Count!G5)) | H5: =IF(C5="","",IF($D5="A","Gateway Není",Count!N5)) | I5: =IF(C5="","",IF($D5="A","Switch Není",Count!O5)) | J5: =IF(C5="","",IF($D5="A","Switch Není", Count!P5)) | K5: =IF(C5="","",IF($D5="N",Count!Q5,_xlfn.CONCAT("R1 - ",Count!N5))) | L5: =IF(C5="","",IF($D5="N",Count!R5,_xlfn.CONCAT("R2 - ",Count!Q5))) | M5: =IF($B5="","",Count!S5)
A6: Síť 2 | E6: =IF($B6="","",Count!L6) | F6: =IF($B6="","",Count!M6) | G6: =IF($B6="","",_xlfn.CONCAT("/",Count!G6)) | H6: =IF(C6="","",IF($D6="A","Gateway Není",Count!N6)) | I6: =IF(C6="","",IF($D6="A","Switch Není",Count!O6)) | J6: =IF(C6="","",IF($D6="A","Switch Není", Count!P6)) | K6: =IF(C6="","",IF($D6="N",Count!Q6,_xlfn.CONCAT("R1 - ",Count!N6))) | L6: =IF(C6="","",IF($D6="N",Count!R6,_xlfn.CONCAT("R2 - ",Count!Q6))) | M6: =IF($B6="","",Count!S6)
A7: Síť 3 | E7: =IF($B7="","",Count!L7) | F7: =IF($B7="","",Count!M7) | G7: =IF($B7="","",_xlfn.CONCAT("/",Count!G7)) | H7: =IF(C7="","",IF($D7="A","Gateway Není",Count!N7)) | I7: =IF(C7="","",IF($D7="A","Switch Není",Count!O7)) | J7: =IF(C7="","",IF($D7="A","Switch Není", Count!P7)) | K7: =IF(C7="","",IF($D7="N",Count!Q7,_xlfn.CONCAT("R1 - ",Count!N7))) | L7: =IF(C7="","",IF($D7="N",Count!R7,_xlfn.CONCAT("R2 - ",Count!Q7))) | M7: =IF($B7="","",Count!S7)
A8: Síť 4 | E8: =IF($B8="","",Count!L8) | F8: =IF($B8="","",Count!M8) | G8: =IF($B8="","",_xlfn.CONCAT("/",Count!G8)) | H8: =IF(C8="","",IF($D8="A","Gateway Není",Count!N8)) | I8: =IF(C8="","",IF($D8="A","Switch Není",Count!O8)) | J8: =IF(C8="","",IF($D8="A","Switch Není", Count!P8)) | K8: =IF(C8="","",IF($D8="N",Count!Q8,_xlfn.CONCAT("R1 - ",Count!N8))) | L8: =IF(C8="","",IF($D8="N",Count!R8,_xlfn.CONCAT("R2 - ",Count!Q8))) | M8: =IF($B8="","",Count!S8)
A9: Síť 5 | E9: =IF($B9="","",Count!L9) | F9: =IF($B9="","",Count!M9) | G9: =IF($B9="","",_xlfn.CONCAT("/",Count!G9)) | H9: =IF(C9="","",IF($D9="A","Gateway Není",Count!N9)) | I9: =IF(C9="","",IF($D9="A","Switch Není",Count!O9)) | J9: =IF(C9="","",IF($D9="A","Switch Není", Count!P9)) | K9: =IF(C9="","",IF($D9="N",Count!Q9,_xlfn.CONCAT("R1 - ",Count!N9))) | M9: =IF($B9="","",Count!S9)
A10: Síť 6 | E10: =IF($B10="","",Count!L10) | F10: =IF($B10="","",Count!M10) | G10: =IF($B10="","",_xlfn.CONCAT("/",Count!G10)) | H10: =IF(C10="","",IF($D10="A","Gateway Není",Count!N10)) | I10: =IF(C10="","",IF($D10="A","Switch Není",Count!O10)) | J10: =IF(C10="","",IF($D10="A","Switch Není", Count!P10)) | K10: =IF(C10="","",IF($D10="N",Count!Q10,_xlfn.CONCAT("R1 - ",Count!N10))) | L10: =IF(C10="","",IF($D10="N",Count!R10,_xlfn.CONCAT("R2 - ",Count!Q10))) | M10: =IF($B10="","",Count!S10)
A11: Síť 7 | E11: =IF($B11="","",Count!L11) | F11: =IF($B11="","",Count!M11) | G11: =IF($B11="","",_xlfn.CONCAT("/",Count!G11)) | H11: =IF(C11="","",IF($D11="A","Gateway Není",Count!N11)) | I11: =IF(C11="","",IF($D11="A","Switch Není",Count!O11)) | J11: =IF(C11="","",IF($D11="A","Switch Není", Count!P11)) | K11: =IF(C11="","",IF($D11="N",Count!Q11,_xlfn.CONCAT("R1 - ",Count!N11))) | L11: =IF(C11="","",IF($D11="N",Count!R11,_xlfn.CONCAT("R2 - ",Count!Q11))) | M11: =IF($B11="","",Count!S11)
A12: Síť 8 | E12: =IF($B12="","",Count!L12) | F12: =IF($B12="","",Count!M12) | G12: =IF($B12="","",_xlfn.CONCAT("/",Count!G12)) | H12: =IF(C12="","",IF($D12="A","Gateway Není",Count!N12)) | I12: =IF(C12="","",IF($D12="A","Switch Není",Count!O12)) | J12: =IF(C12="","",IF($D12="A","Switch Není", Count!P12)) | K12: =IF(C12="","",IF($D12="N",Count!Q12,_xlfn.CONCAT("R1 - ",Count!N12))) | L12: =IF(C12="","",IF($D12="N",Count!R12,_xlfn.CONCAT("R2 - ",Count!Q12))) | M12: =IF($B12="","",Count!S12)
A13: Síť 9 | E13: =IF($B13="","",Count!L13) | F13: =IF($B13="","",Count!M13) | G13: =IF($B13="","",_xlfn.CONCAT("/",Count!G13)) | H13: =IF(C13="","",IF($D13="A","Gateway Není",Count!N13)) | I13: =IF(C13="","",IF($D13="A","Switch Není",Count!O13)) | J13: =IF(C13="","",IF($D13="A","Switch Není", Count!P13)) | K13: =IF(C13="","",IF($D13="N",Count!Q13,_xlfn.CONCAT("R1 - ",Count!N13))) | L13: =IF(C13="","",IF($D13="N",Count!R13,_xlfn.CONCAT("R2 - ",Count!Q13))) | M13: =IF($B13="","",Count!S13)
A14: Síť 10 | E14: =IF($B14="","",Count!L14) | F14: =IF($B14="","",Count!M14) | G14: =IF($B14="","",_xlfn.CONCAT("/",Count!G14)) | H14: =IF(C14="","",IF($D14="A","Gateway Není",Count!N14)) | I14: =IF(C14="","",IF($D14="A","Switch Není",Count!O14)) | J14: =IF(C14="","",IF($D14="A","Switch Není", Count!P14)) | K14: =IF(C14="","",IF($D14="N",Count!Q14,_xlfn.CONCAT("R1 - ",Count!N14))) | L14: =IF(C14="","",IF($D14="N",Count!R14,_xlfn.CONCAT("R2 - ",Count!Q14))) | M14: =IF($B14="","",Count!S14)
A15: Síť 11 | E15: =IF($B15="","",Count!L15) | F15: =IF($B15="","",Count!M15) | G15: =IF($B15="","",_xlfn.CONCAT("/",Count!G15)) | H15: =IF(C15="","",IF($D15="A","Gateway Není",Count!N15)) | I15: =IF(C15="","",IF($D15="A","Switch Není",Count!O15)) | J15: =IF(C15="","",IF($D15="A","Switch Není", Count!P15)) | K15: =IF(C15="","",IF($D15="N",Count!Q15,_xlfn.CONCAT("R1 - ",Count!N15))) | L15: =IF(C15="","",IF($D15="N",Count!R15,_xlfn.CONCAT("R2 - ",Count!Q15))) | M15: =IF($B15="","",Count!S15)
A16: Síť 12 | E16: =IF($B16="","",Count!L16) | F16: =IF($B16="","",Count!M16) | G16: =IF($B16="","",_xlfn.CONCAT("/",Count!G16)) | H16: =IF(C16="","",IF($D16="A","Gateway Není",Count!N16)) | I16: =IF(C16="","",IF($D16="A","Switch Není",Count!O16)) | J16: =IF(C16="","",IF($D16="A","Switch Není", Count!P16)) | K16: =IF(C16="","",IF($D16="N",Count!Q16,_xlfn.CONCAT("R1 - ",Count!N16))) | L16: =IF(C16="","",IF($D16="N",Count!R16,_xlfn.CONCAT("R2 - ",Count!Q16))) | M16: =IF($B16="","",Count!S16)
A17: Síť 13 | E17: =IF($B17="","",Count!L17) | F17: =IF($B17="","",Count!M17) | G17: =IF($B17="","",_xlfn.CONCAT("/",Count!G17)) | H17: =IF(C17="","",IF($D17="A","Gateway Není",Count!N17)) | I17: =IF(C17="","",IF($D17="A","Switch Není",Count!O17)) | J17: =IF(C17="","",IF($D17="A","Switch Není", Count!P17)) | K17: =IF(C17="","",IF($D17="N",Count!Q17,_xlfn.CONCAT("R1 - ",Count!N17))) | L17: =IF(C17="","",IF($D17="N",Count!R17,_xlfn.CONCAT("R2 - ",Count!Q17))) | M17: =IF($B17="","",Count!S17)
A18: Síť 14 | E18: =IF($B18="","",Count!L18) | F18: =IF($B18="","",Count!M18) | G18: =IF($B18="","",_xlfn.CONCAT("/",Count!G18)) | H18: =IF(C18="","",IF($D18="A","Gateway Není",Count!N18)) | I18: =IF(C18="","",IF($D18="A","Switch Není",Count!O18)) | J18: =IF(C18="","",IF($D18="A","Switch Není", Count!P18)) | K18: =IF(C18="","",IF($D18="N",Count!Q18,_xlfn.CONCAT("R1 - ",Count!N18))) | L18: =IF(C18="","",IF($D18="N",Count!R18,_xlfn.CONCAT("R2 - ",Count!Q18))) | M18: =IF($B18="","",Count!S18)
A19: Síť 15 | E19: =IF($B19="","",Count!L19) | F19: =IF($B19="","",Count!M19) | G19: =IF($B19="","",_xlfn.CONCAT("/",Count!G19)) | H19: =IF(C19="","",IF($D19="A","Gateway Není",Count!N19)) | I19: =IF(C19="","",IF($D19="A","Switch Není",Count!O19)) | J19: =IF(C19="","",IF($D19="A","Switch Není", Count!P19)) | K19: =IF(C19="","",IF($D19="N",Count!Q19,_xlfn.CONCAT("R1 - ",Count!N19))) | L19: =IF(C19="","",IF($D19="N",Count!R19,_xlfn.CONCAT("R2 - ",Count!Q19))) | M19: =IF($B19="","",Count!S19)
A20: Síť 16 | E20: =IF($B20="","",Count!L20) | F20: =IF($B20="","",Count!M20) | G20: =IF($B20="","",_xlfn.CONCAT("/",Count!G20)) | H20: =IF(C20="","",IF($D20="A","Gateway Není",Count!N20)) | I20: =IF(C20="","",IF($D20="A","Switch Není",Count!O20)) | J20: =IF(C20="","",IF($D20="A","Switch Není", Count!P20)) | K20: =IF(C20="","",IF($D20="N",Count!Q20,_xlfn.CONCAT("R1 - ",Count!N20))) | L20: =IF(C20="","",IF($D20="N",Count!R20,_xlfn.CONCAT("R2 - ",Count!Q20))) | M20: =IF($B20="","",Count!S20)
A21: Síť 17 | E21: =IF($B21="","",Count!L21) | F21: =IF($B21="","",Count!M21) | G21: =IF($B21="","",_xlfn.CONCAT("/",Count!G21)) | H21: =IF(C21="","",IF($D21="A","Gateway Není",Count!N21)) | I21: =IF(C21="","",IF($D21="A","Switch Není",Count!O21)) | J21: =IF(C21="","",IF($D21="A","Switch Není", Count!P21)) | K21: =IF(C21="","",IF($D21="N",Count!Q21,_xlfn.CONCAT("R1 - ",Count!N21))) | L21: =IF(C21="","",IF($D21="N",Count!R21,_xlfn.CONCAT("R2 - ",Count!Q21))) | M21: =IF($B21="","",Count!S21)
... A60: Síť 56 | E60: =IF($B60="","",Count!L60) | F60: =IF($B60="","",Count!M60) | G60: =IF($B60="","",_xlfn.CONCAT("/",Count!G60)) | H60: =IF(C60="","",IF($D60="A","Gateway Není",Count!N60)) | I60: =IF(C60="","",IF($D60="A","Switch Není",Count!O60)) | J60: =IF(C60="","",IF($D60="A","Switch Není", Count!P60)) | K60: =IF(C60="","",IF($D60="N",Count!Q60,_xlfn.CONCAT("R1 - ",Count!N60))) | L60: =IF(C60="","",IF($D60="N",Count!R60,_xlfn.CONCAT("R2 - ",Count!Q60))) | M60: =IF($B60="","",Count!S60)

Sheet Count
A1: =LEFT(Base!B2, FIND("~", SUBSTITUTE(Base!B2,".","~",2))) -> #VALUE!
B2: =Base!B2 -> 0
A3: 172.16.1.1
A4: Name/Color | B4: Host Req. (PC) | C4: SW Count | D4: Total Req. (H) | E4: Host Bits (h) | F4: Block Size | G4: Prefix (PR) | H4: FIRST OCT | I4: SECOND OCT | J4: THIRD OCT | K4: FOURTH OCT | L4: AS (IP) | M4: Maska (MA) | N4: Gateway (GW) | O4: SW First | P4: SW Last | Q4: PC First | R4: PC Last | S4: Broadcast (BR)
A5: =Base!A5 -> Síť 1 | B5: =Base!B5 -> 0 | C5: =Base!C5 -> 0 | D5: =B5+C5+2 -> 2 | E5: =ROUNDUP(LOG(D5,2),0) -> 1 | F5: =POWER(2,E5) -> 2 | G5: =32-E5 -> 31 | H5: =VALUE(RIGHT(B2,LEN(B2)-FIND(".",B2,FIND(".",B2,FIND(".",B2)+1)+1))) -> #VALUE! | I5: =VALUE(MID(B2,FIND(".",B2,FIND(".",B2)+1)+1,FIND(".",B2,FIND(".",B2,FIND(".",B2)+1)+1)-FIND(".",B2,FIND(".",B2)+1)-1)) -> #VALUE! | J5: =VALUE(MID(B2,FIND(".",B2)+1,FIND(".",B2,FIND(".",B2)+1)-FIND(".",B2)-1)) -> #VALUE! | K5: =VALUE(LEFT(B2,FIND(".",B2)-1)) -> #VALUE! | L5: =CONCATENATE("192.168.",I5,".",H5) -> #VALUE! | M5: =VLOOKUP(G5, MaskTable!A:B, 2, FALSE) -> 255.255.255.254 | N5: =CONCATENATE("192.168.",I5,".",H5+1) -> #VALUE! | O5: =IF(C5>0, CONCATENATE("192.168.",I5,".",H5+2), "N/A") -> N/A | P5: =IF(C5>0, CONCATENATE("192.168.",I5,".",H5+1+C5), "N/A") -> N/A | Q5: =CONCATENATE("192.168.",I5,".",IF(C5=0, H5+2, H5+2+C5)) -> #VALUE! | R5: =CONCATENATE("192.168.",I5,".",H5+F5-2) -> #VALUE! | S5: =CONCATENATE("192.168.",I5,".",H5+F5-1) -> #VALUE!
A6: =Base!A6 -> Síť 2 | B6: =Base!B6 -> 0 | C6: =Base!C6 -> 0 | D6: =B6+C6+2 -> 2 | E6: =ROUNDUP(LOG(D6,2),0) -> 1 | F6: =POWER(2,E6) -> 2 | G6: =32-E6 -> 31 | H6: =MOD(H5+F5,256) -> #VALUE! | I6: =I5+TRUNC((H5+F5)/256) -> #VALUE! | L6: =CONCATENATE("192.168.",I6,".",H6) -> #VALUE! | M6: =VLOOKUP(G6, MaskTable!A:B, 2, FALSE) -> 255.255.255.254 | N6: =CONCATENATE("192.168.",I6,".",H6+1) -> #VALUE! | O6: =IF(C6>0, CONCATENATE("192.168.",I6,".",H6+2), "N/A") -> N/A | P6: =IF(C6>0, CONCATENATE("192.168.",I6,".",H6+1+C6), "N/A") -> N/A | Q6: =CONCATENATE("192.168.",I6,".",IF(C6=0, H6+2, H6+2+C6)) -> #VALUE! | R6: =CONCATENATE("192.168.",I6,".",H6+F6-2) -> #VALUE! | S6: =CONCATENATE("192.168.",I6,".",H6+F6-1) -> #VALUE!
A7: =Base!A7 -> Síť 3 | B7: =Base!B7 -> 0 | C7: =Base!C7 -> 0 | D7: =B7+C7+2 -> 2 | E7: =ROUNDUP(LOG(D7,2),0) -> 1 | F7: =POWER(2,E7) -> 2 | G7: =32-E7 -> 31 | H7: =MOD(H6+F6,256) -> #VALUE! | I7: =I6+TRUNC((H6+F6)/256) -> #VALUE! | L7: =CONCATENATE("192.168.",I7,".",H7) -> #VALUE! | M7: =VLOOKUP(G7, MaskTable!A:B, 2, FALSE) -> 255.255.255.254 | N7: =CONCATENATE("192.168.",I7,".",H7+1) -> #VALUE! | O7: =IF(C7>0, CONCATENATE("192.168.",I7,".",H7+2), "N/A") -> N/A | P7: =IF(C7>0, CONCATENATE("192.168.",I7,".",H7+1+C7), "N/A") -> N/A | Q7: =CONCATENATE("192.168.",I7,".",IF(C7=0, H7+2, H7+2+C7)) -> #VALUE! | R7: =CONCATENATE("192.168.",I7,".",H7+F7-2) -> #VALUE! | S7: =CONCATENATE("192.168.",I7,".",H7+F7-1) -> #VALUE!
A8: =Base!A8 -> Síť 4 | B8: =Base!B8 -> 0 | C8: =Base!C8 -> 0 | D8: =B8+C8+2 -> 2 | E8: =ROUNDUP(LOG(D8,2),0) -> 1 | F8: =POWER(2,E8) -> 2 | G8: =32-E8 -> 31 | H8: =MOD(H7+F7,256) -> #VALUE! | I8: =I7+TRUNC((H7+F7)/256) -> #VALUE! | L8: =CONCATENATE("192.168.",I8,".",H8) -> #VALUE! | M8: =VLOOKUP(G8, MaskTable!A:B, 2, FALSE) -> 255.255.255.254 | N8: =CONCATENATE("192.168.",I8,".",H8+1) -> #VALUE! | O8: =IF(C8>0, CONCATENATE("192.168.",I8,".",H8+2), "N/A") -> N/A | P8: =IF(C8>0, CONCATENATE("192.168.",I8,".",H8+1+C8), "N/A") -> N/A | Q8: =CONCATENATE("192.168.",I8,".",IF(C8=0, H8+2, H8+2+C8)) -> #VALUE! | R8: =CONCATENATE("192.168.",I8,".",H8+F8-2) -> #VALUE! | S8: =CONCATENATE("192.168.",I8,".",H8+F8-1) -> #VALUE!
A9: =Base!A9 -> Síť 5 | B9: =Base!B9 -> 0 | C9: =Base!C9 -> 0 | D9: =B9+C9+2 -> 2 | E9: =ROUNDUP(LOG(D9,2),0) -> 1 | F9: =POWER(2,E9) -> 2 | G9: =32-E9 -> 31 | H9: =MOD(H8+F8,256) -> #VALUE! | I9: =I8+TRUNC((H8+F8)/256) -> #VALUE! | L9: =CONCATENATE("192.168.",I9,".",H9) -> #VALUE! | M9: =VLOOKUP(G9, MaskTable!A:B, 2, FALSE) -> 255.255.255.254 | N9: =CONCATENATE("192.168.",I9,".",H9+1) -> #VALUE! | O9: =IF(C9>0, CONCATENATE("192.168.",I9,".",H9+2), "N/A") -> N/A | P9: =IF(C9>0, CONCATENATE("192.168.",I9,".",H9+1+C9), "N/A") -> N/A | Q9: =CONCATENATE("192.168.",I9,".",IF(C9=0, H9+2, H9+2+C9)) -> #VALUE! | R9: =CONCATENATE("192.168.",I9,".",H9+F9-2) -> #VALUE! | S9: =CONCATENATE("192.168.",I9,".",H9+F9-1) -> #VALUE!
A10: =Base!A10 -> Síť 6 | B10: =Base!B10 -> 0 | C10: =Base!C10 -> 0 | D10: =B10+C10+2 -> 2 | E10: =ROUNDUP(LOG(D10,2),0) -> 1 | F10: =POWER(2,E10) -> 2 | G10: =32-E10 -> 31 | H10: =MOD(H9+F9,256) -> #VALUE! | I10: =I9+TRUNC((H9+F9)/256) -> #VALUE! | L10: =CONCATENATE("192.168.",I10,".",H10) -> #VALUE! | M10: =VLOOKUP(G10, MaskTable!A:B, 2, FALSE) -> 255.255.255.254 | N10: =CONCATENATE("192.168.",I10,".",H10+1) -> #VALUE! | O10: =IF(C10>0, CONCATENATE("192.168.",I10,".",H10+2), "N/A") -> N/A | P10: =IF(C10>0, CONCATENATE("192.168.",I10,".",H10+1+C10), "N/A") -> N/A | Q10: =CONCATENATE("192.168.",I10,".",IF(C10=0, H10+2, H10+2+C10)) -> #VALUE! | R10: =CONCATENATE("192.168.",I10,".",H10+F10-2) -> #VALUE! | S10: =CONCATENATE("192.168.",I10,".",H10+F10-1) -> #VALUE!
A11: =Base!A11 -> Síť 7 | B11: =Base!B11 -> 0 | C11: =Base!C11 -> 0 | D11: =B11+C11+2 -> 2 | E11: =ROUNDUP(LOG(D11,2),0) -> 1 | F11: =POWER(2,E11) -> 2 | G11: =32-E11 -> 31 | H11: =MOD(H10+F10,256) -> #VALUE! | I11: =I10+TRUNC((H10+F10)/256) -> #VALUE! | L11: =CONCATENATE("192.168.",I11,".",H11) -> #VALUE! | M11: =VLOOKUP(G11, MaskTable!A:B, 2, FALSE) -> 255.255.255.254 | N11: =CONCATENATE("192.168.",I11,".",H11+1) -> #VALUE! | O11: =IF(C11>0, CONCATENATE("192.168.",I11,".",H11+2), "N/A") -> N/A | P11: =IF(C11>0, CONCATENATE("192.168.",I11,".",H11+1+C11), "N/A") -> N/A | Q11: =CONCATENATE("192.168.",I11,".",IF(C11=0, H11+2, H11+2+C11)) -> #VALUE! | R11: =CONCATENATE("192.168.",I11,".",H11+F11-2) -> #VALUE! | S11: =CONCATENATE("192.168.",I11,".",H11+F11-1) -> #VALUE!
A12: =Base!A12 -> Síť 8 | B12: =Base!B12 -> 0 | C12: =Base!C12 -> 0 | D12: =B12+C12+2 -> 2 | E12: =ROUNDUP(LOG(D12,2),0) -> 1 | F12: =POWER(2,E12) -> 2 | G12: =32-E12 -> 31 | H12: =MOD(H11+F11,256) -> #VALUE! | I12: =I11+TRUNC((H11+F11)/256) -> #VALUE! | L12: =CONCATENATE("192.168.",I12,".",H12) -> #VALUE! | M12: =VLOOKUP(G12, MaskTable!A:B, 2, FALSE) -> 255.255.255.254 | N12: =CONCATENATE("192.168.",I12,".",H12+1) -> #VALUE! | O12: =IF(C12>0, CONCATENATE("192.168.",I12,".",H12+2), "N/A") -> N/A | P12: =IF(C12>0, CONCATENATE("192.168.",I12,".",H12+1+C12), "N/A") -> N/A | Q12: =CONCATENATE("192.168.",I12,".",IF(C12=0, H12+2, H12+2+C12)) -> #VALUE! | R12: =CONCATENATE("192.168.",I12,".",H12+F12-2) -> #VALUE! | S12: =CONCATENATE("192.168.",I12,".",H12+F12-1) -> #VALUE!
A13: =Base!A13 -> Síť 9 | B13: =Base!B13 -> 0 | C13: =Base!C13 -> 0 | D13: =B13+C13+2 -> 2 | E13: =ROUNDUP(LOG(D13,2),0) -> 1 | F13: =POWER(2,E13) -> 2 | G13: =32-E13 -> 31 | H13: =MOD(H12+F12,256) -> #VALUE! | I13: =I12+TRUNC((H12+F12)/256) -> #VALUE! | L13: =CONCATENATE("192.168.",I13,".",H13) -> #VALUE! | M13: =VLOOKUP(G13, MaskTable!A:B, 2, FALSE) -> 255.255.255.254 | N13: =CONCATENATE("192.168.",I13,".",H13+1) -> #VALUE! | O13: =IF(C13>0, CONCATENATE("192.168.",I13,".",H13+2), "N/A") -> N/A | P13: =IF(C13>0, CONCATENATE("192.168.",I13,".",H13+1+C13), "N/A") -> N/A | Q13: =CONCATENATE("192.168.",I13,".",IF(C13=0, H13+2, H13+2+C13)) -> #VALUE! | R13: =CONCATENATE("192.168.",I13,".",H13+F13-2) -> #VALUE! | S13: =CONCATENATE("192.168.",I13,".",H13+F13-1) -> #VALUE!
A14: =Base!A14 -> Síť 10 | B14: =Base!B14 -> 0 | C14: =Base!C14 -> 0 | D14: =B14+C14+2 -> 2 | E14: =ROUNDUP(LOG(D14,2),0) -> 1 | F14: =POWER(2,E14) -> 2 | G14: =32-E14 -> 31 | H14: =MOD(H13+F13,256) -> #VALUE! | I14: =I13+TRUNC((H13+F13)/256) -> #VALUE! | L14: =CONCATENATE("192.168.",I14,".",H14) -> #VALUE! | M14: =VLOOKUP(G14, MaskTable!A:B, 2, FALSE) -> 255.255.255.254 | N14: =CONCATENATE("192.168.",I14,".",H14+1) -> #VALUE! | O14: =IF(C14>0, CONCATENATE("192.168.",I14,".",H14+2), "N/A") -> N/A | P14: =IF(C14>0, CONCATENATE("192.168.",I14,".",H14+1+C14), "N/A") -> N/A | Q14: =CONCATENATE("192.168.",I14,".",IF(C14=0, H14+2, H14+2+C14)) -> #VALUE! | R14: =CONCATENATE("192.168.",I14,".",H14+F14-2) -> #VALUE! | S14: =CONCATENATE("192.168.",I14,".",H14+F14-1) -> #VALUE!
A15: =Base!A15 -> Síť 11 | B15: =Base!B15 -> 0 | C15: =Base!C15 -> 0 | D15: =B15+C15+2 -> 2 | E15: =ROUNDUP(LOG(D15,2),0) -> 1 | F15: =POWER(2,E15) -> 2 | G15: =32-E15 -> 31 | H15: =MOD(H14+F14,256) -> #VALUE! | I15: =I14+TRUNC((H14+F14)/256) -> #VALUE! | L15: =CONCATENATE("192.168.",I15,".",H15) -> #VALUE! | M15: =VLOOKUP(G15, MaskTable!A:B, 2, FALSE) -> 255.255.255.254 | N15: =CONCATENATE("192.168.",I15,".",H15+1) -> #VALUE! | O15: =IF(C15>0, CONCATENATE("192.168.",I15,".",H15+2), "N/A") -> N/A | P15: =IF(C15>0, CONCATENATE("192.168.",I15,".",H15+1+C15), "N/A") -> N/A | Q15: =CONCATENATE("192.168.",I15,".",IF(C15=0, H15+2, H15+2+C15)) -> #VALUE! | R15: =CONCATENATE("192.168.",I15,".",H15+F15-2) -> #VALUE! | S15: =CONCATENATE("192.168.",I15,".",H15+F15-1) -> #VALUE!
A16: =Base!A16 -> Síť 12 | B16: =Base!B16 -> 0 | C16: =Base!C16 -> 0 | D16: =B16+C16+2 -> 2 | E16: =ROUNDUP(LOG(D16,2),0) -> 1 | F16: =POWER(2,E16) -> 2 | G16: =32-E16 -> 31 | H16: =MOD(H15+F15,256) -> #VALUE! | I16: =I15+TRUNC((H15+F15)/256) -> #VALUE! | L16: =CONCATENATE("192.168.",I16,".",H16) -> #VALUE! | M16: =VLOOKUP(G16, MaskTable!A:B, 2, FALSE) -> 255.255.255.254 | N16: =CONCATENATE("192.168.",I16,".",H16+1) -> #VALUE! | O16: =IF(C16>0, CONCATENATE("192.168.",I16,".",H16+2), "N/A") -> N/A | P16: =IF(C16>0, CONCATENATE("192.168.",I16,".",H16+1+C16), "N/A") -> N/A | Q16: =CONCATENATE("192.168.",I16,".",IF(C16=0, H16+2, H16+2+C16)) -> #VALUE! | R16: =CONCATENATE("192.168.",I16,".",H16+F16-2) -> #VALUE! | S16: =CONCATENATE("192.168.",I16,".",H16+F16-1) -> #VALUE!
A17: =Base!A17 -> Síť 13 | B17: =Base!B17 -> 0 | C17: =Base!C17 -> 0 | D17: =B17+C17+2 -> 2 | E17: =ROUNDUP(LOG(D17,2),0) -> 1 | F17: =POWER(2,E17) -> 2 | G17: =32-E17 -> 31 | H17: =MOD(H16+F16,256) -> #VALUE! | I17: =I16+TRUNC((H16+F16)/256) -> #VALUE! | L17: =CONCATENATE("192.168.",I17,".",H17) -> #VALUE! | M17: =VLOOKUP(G17, MaskTable!A:B, 2, FALSE) -> 255.255.255.254 | N17: =CONCATENATE("192.168.",I17,".",H17+1) -> #VALUE! | O17: =IF(C17>0, CONCATENATE("192.168.",I17,".",H17+2), "N/A") -> N/A | P17: =IF(C17>0, CONCATENATE("192.168.",I17,".",H17+1+C17), "N/A") -> N/A | Q17: =CONCATENATE("192.168.",I17,".",IF(C17=0, H17+2, H17+2+C17)) -> #VALUE! | R17: =CONCATENATE("192.168.",I17,".",H17+F17-2) -> #VALUE! | S17: =CONCATENATE("192.168.",I17,".",H17+F17-1) -> #VALUE!
... A19: =Base!A19 -> Síť 15 | B19: =Base!B19 -> 0 | C19: =Base!C19 -> 0 | D19: =B19+C19+2 -> 2 | E19: =ROUNDUP(LOG(D19,2),0) -> 1 | F19: =POWER(2,E19) -> 2 | G19: =32-E19 -> 31 | H19: =MOD(H18+F18,256) -> #VALUE! | I19: =I18+TRUNC((H18+F18)/256) -> #VALUE! | L19: =CONCATENATE("192.168.",I19,".",H19) -> #VALUE! | M19: =VLOOKUP(G19, MaskTable!A:B, 2, FALSE) -> 255.255.255.254 | N19: =CONCATENATE("192.168.",I19,".",H19+1) -> #VALUE! | O19: =IF(C19>0, CONCATENATE("192.168.",I19,".",H19+2), "N/A") -> N/A | P19: =IF(C19>0, CONCATENATE("192.168.",I19,".",H19+1+C19), "N/A") -> N/A | Q19: =CONCATENATE("192.168.",I19,".",IF(C19=0, H19+2, H19+2+C19)) -> #VALUE! | R19: =CONCATENATE("192.168.",I19,".",H19+F19-2) -> #VALUE! | S19: =CONCATENATE("192.168.",I19,".",H19+F19-1) -> #VALUE!
A20: =Base!A20 -> Síť 16 | B20: =B20 -> 0 | C20: =Base!C20 -> 0 | D20: =B20+C20+2 -> 2 | E20: =ROUNDUP(LOG(D20,2),0) -> 1 | F20: =POWER(2,E20) -> 256 | G20: =32-E20 -> 31 | H20: =MOD(H19+F19,256) -> #VALUE! | I20: =I19+TRUNC((H19+F19)/256) -> #VALUE! | L20: =CONCATENATE("192.168.",I20,".",H20) -> #VALUE! | M20: =VLOOKUP(G20, MaskTable!A:B, 2, FALSE) -> 255.255.255.128 | N20: =CONCATENATE("192.168.",I20,".",H20+1) -> #VALUE! | O20: =IF(C20>0, CONCATENATE("192.168.",I20,".",H20+2), "N/A") -> N/A | P20: =IF(C20>0, CONCATENATE("192.168.",I20,".",H20+1+C20), "N/A") -> N/A | Q20: =CONCATENATE("192.168.",I20,".",IF(C20=0, H20+2, H20+2+C20)) -> #VALUE! | R20: =CONCATENATE("192.168.",I20,".",H20+F20-2) -> 192.168.2.126 | S20: =CONCATENATE("192.168.",I20,".",H20+F20-1) -> 192.168.2.127
A21: =Base!A21 -> Síť 17 | B21: =B21 -> 0 | C21: =Base!C21 -> 0 | D21: =B21+C21+2 -> 2 | E21: =ROUNDUP(LOG(D21,2),0) -> 1 | F21: =POWER(2,E21) -> 256 | G21: =32-E21 -> 31 | H21: =MOD(H20+F20,256) -> 0 | I21: =I20+TRUNC((H20+F20)/256) -> 2 | L21: =CONCATENATE("192.168.",I21,".",H21) -> 192.168.2.0 | M21: =VLOOKUP(G21, MaskTable!A:B, 2, FALSE) -> 255.255.255.128 | N21: =CONCATENATE("192.168.",I21,".",H21+1) -> 192.168.2.1 | O21: =IF(C21>0, CONCATENATE("192.168.",I21,".",H21+2), "N/A") -> N/A | P21: =IF(C21>0, CONCATENATE("192.168.",I21,".",H21+1+C21), "N/A") -> N/A | Q21: =CONCATENATE("192.168.",I21,".",IF(C21=0, H21+2, H21+2+C21)) -> 192.168.2.3 | R21: =CONCATENATE("192.168.",I21,".",H21+F21-2) -> 192.168.2.126 | S21: =CONCATENATE("192.168.",I21,".",H21+F21-1) -> 192.168.2.127
A22: =Base!A22 -> Síť 18 | B22: =B22 -> 0 | C22: =Base!C22 -> 0 | D22: =B22+C22+2 -> 2 | E22: =ROUNDUP(LOG(D22,2),0) -> 1 | F22: =POWER(2,E22) -> 256 | G22: =32-E22 -> 31 | H22: =MOD(H21+F21,256) -> 0 | I22: =I21+TRUNC((H21+F21)/256) -> 2 | L22: =CONCATENATE("192.168.",I22,".",H22) -> 192.168.2.0 | M22: =VLOOKUP(G22, MaskTable!A:B, 2, FALSE) -> 255.255.255.128 | N22: =CONCATENATE("192.168.",I22,".",H22+1) -> 192.168.2.1 | O22: =IF(C22>0, CONCATENATE("192.168.",I22,".",H22+2), "N/A") -> N/A | P22: =IF(C22>0, CONCATENATE("192.168.",I22,".",H22+1+C22), "N/A") -> N/A | Q22: =CONCATENATE("192.168.",I22,".",IF(C22=0, H22+2, H22+2+C22)) -> 192.168.2.3 | R22: =CONCATENATE("192.168.",I22,".",H22+F22-2) -> 192.168.2.126 | S22: =CONCATENATE("192.168.",I22,".",H22+F22-1) -> 192.168.2.127
A23: =Base!A23 -> Síť 19 | B23: =B23 -> 0 | C23: =Base!C23 -> 0 | D23: =B23+C23+2 -> 2 | E23: =ROUNDUP(LOG(D23,2),0) -> 1 | F23: =POWER(2,E23) -> 256 | G23: =32-E23 -> 31 | H23: =MOD(H22+F22,256) -> 0 | I23: =I22+TRUNC((H22+F22)/256) -> 2 | L23: =CONCATENATE("192.168.",I23,".",H23) -> 192.168.2.0 | M23: =VLOOKUP(G23, MaskTable!A:B, 2, FALSE) -> 255.255.255.128 | N23: =CONCATENATE("192.168.",I23,".",H23+1) -> 192.168.2.1 | O23: =IF(C23>0, CONCATENATE("192.168.",I23,".",H23+2), "N/A") -> N/A | P23: =IF(C23>0, CONCATENATE("192.168.",I23,".",H23+1+C23), "N/A") -> N/A | Q23: =CONCATENATE("192.168.",I23,".",IF(C23=0, H23+2, H23+2+C23)) -> 192.168.2.3 | R23: =CONCATENATE("192.168.",I23,".",H23+F23-2) -> 192.168.2.126 | S23: =CONCATENATE("192.168.",I23,".",H23+F23-1) -> 192.168.2.127
A24: =Base!A24 -> Síť 20 | B24: =B24 -> 0 | C24: =Base!C24 -> 0 | D24: =B24+C24+2 -> 2 | E24: =ROUNDUP(LOG(D24,2),0) -> 1 | F24: =POWER(2,E24) -> 256 | G24: =32-E24 -> 31 | H24: =MOD(H23+F23,256) -> 0 | I24: =I23+TRUNC((H23+F23)/256) -> 2 | L24: =CONCATENATE("192.168.",I24,".",H24) -> 192.168.2.0 | M24: =VLOOKUP(G24, MaskTable!A:B, 2, FALSE) -> 255.255.255.128 | N24: =CONCATENATE("192.168.",I24,".",H24+1) -> 192.168.2.1 | O24: =IF(C24>0, CONCATENATE("192.168.",I24,".",H24+2), "N/A") -> N/A | P24: =IF(C24>0, CONCATENATE("192.168.",I24,".",H24+1+C24), "N/A") -> N/A | Q24: =CONCATENATE("192.168.",I24,".",IF(C24=0, H24+2, H24+2+C24)) -> 192.168.2.3 | R24: =CONCATENATE("192.168.",I24,".",H24+F24-2) -> 192.168.2.126 | S24: =CONCATENATE("192.168.",I24,".",H24+F24-1) -> 192.168.2.127
A25: =Base!A25 -> Síť 21 | B25: =B25 -> 0 | C25: =Base!C25 -> 0 | D25: =B25+C25+2 -> 2 | E25: =ROUNDUP(LOG(D25,2),0) -> 1 | F25: =POWER(2,E25) -> 256 | G25: =32-E25 -> 31 | H25: =MOD(H24+F24,256) -> 0 | I25: =I24+TRUNC((H24+F24)/256) -> 2 | L25: =CONCATENATE("192.168.",I25,".",H25) -> 192.168.2.0 | M25: =VLOOKUP(G25, MaskTable!A:B, 2, FALSE) -> 255.255.255.128 | N25: =CONCATENATE("192.168.",I25,".",H25+1) -> 192.168.2.1 | O25: =IF(C25>0, CONCATENATE("192.168.",I25,".",H25+2), "N/A") -> N/A | P25: =IF(C25>0, CONCATENATE("192.168.",I25,".",H25+1+C25), "N/A") -> N/A | Q25: =CONCATENATE("192.168.",I25,".",IF(C25=0, H25+2, H25+2+C25)) -> 192.168.2.3 | R25: =CONCATENATE("192.168.",I25,".",H25+F25-2) -> 192.168.2.126 | S25: =CONCATENATE("192.168.",I25,".",H25+F25-1) -> 192.168.2.127
A26: =Base!A26 -> Síť 22 | B26: =B26 -> 0 | C26: =Base!C26 -> 0 | D26: =B26+C26+2 -> 2 | E26: =ROUNDUP(LOG(D26,2),0) -> 1 | F26: =POWER(2,E26) -> 256 | G26: =32-E26 -> 31 | H26: =MOD(H25+F25,256) -> 0 | I26: =I25+TRUNC((H25+F25)/256) -> 2 | L26: =CONCATENATE("192.168.",I26,".",H26) -> 192.168.2.0 | M26: =VLOOKUP(G26, MaskTable!A:B, 2, FALSE) -> 255.255.255.128 | N26: =CONCATENATE("192.168.",I26,".",H26+1) -> 192.168.2.1 | O26: =IF(C26>0, CONCATENATE("192.168.",I26,".",H26+2), "N/A") -> N/A | P26: =IF(C26>0, CONCATENATE("192.168.",I26,".",H26+1+C26), "N/A") -> N/A | Q26: =CONCATENATE("192.168.",I26,".",IF(C26=0, H26+2, H26+2+C26)) -> 192.168.2.3 | R26: =CONCATENATE("192.168.",I26,".",H26+F26-2) -> 192.168.2.126 | S26: =CONCATENATE("192.168.",I26,".",H26+F26-1) -> 192.168.2.127
A27: =Base!A27 -> Síť 23 | B27: =B27 -> 0 | C27: =Base!C27 -> 0 | D27: =B27+C27+2 -> 2 | E27: =ROUNDUP(LOG(D27,2),0) -> 1 | F27: =POWER(2,E27) -> 256 | G27: =32-E27 -> 31 | H27: =MOD(H26+F26,256) -> 0 | I27: =I26+TRUNC((H26+F26)/256) -> 2 | L27: =CONCATENATE("192.168.",I27,".",H27) -> 192.168.2.0 | M27: =VLOOKUP(G27, MaskTable!A:B, 2, FALSE) -> 255.255.255.128 | N27: =CONCATENATE("192.168.",I27,".",H27+1) -> 192.168.2.1 | O27: =IF(C27>0, CONCATENATE("192.168.",I27,".",H27+2), "N/A") -> N/A | P27: =IF(C27>0, CONCATENATE("192.168.",I27,".",H27+1+C27), "N/A") -> N/A | Q27: =CONCATENATE("192.168.",I27,".",IF(C27=0, H27+2, H27+2+C27)) -> 192.168.2.3 | R27: =CONCATENATE("192.168.",I27,".",H27+F27-2) -> 192.168.2.126 | S27: =CONCATENATE("192.168.",I27,".",H27+F27-1) -> 192.168.2.127
A28: =Base!A28 -> Síť 24 | B28: =B28 -> 0 | C28: =Base!C28 -> 0 | D28: =B28+C28+2 -> 2 | E28: =ROUNDUP(LOG(D28,2),0) -> 1 | F28: =POWER(2,E28) -> 256 | G28: =32-E28 -> 31 | H28: =MOD(H27+F27,256) -> 0 | I28: =I27+TRUNC((H27+F27)/256) -> 2 | L28: =CONCATENATE("192.168.",I28,".",H28) -> 192.168.2.0 | M28: =VLOOKUP(G28, MaskTable!A:B, 2, FALSE) -> 255.255.255.128 | N28: =CONCATENATE("192.168.",I28,".",H28+1) -> 192.168.2.1 | O28: =IF(C28>0, CONCATENATE("192.168.",I28,".",H28+2), "N/A") -> N/A | P28: =IF(C28>0, CONCATENATE("192.168.",I28,".",H28+1+C28), "N/A") -> N/A | Q28: =CONCATENATE("192.168.",I28,".",IF(C28=0, H28+2, H28+2+C28)) -> 192.168.2.3 | R28: =CONCATENATE("192.168.",I28,".",H28+F28-2) -> 192.168.2.126 | S28: =CONCATENATE("192.168.",I28,".",H28+F28-1) -> 192.168.2.127
A29: =Base!A29 -> Síť 25 | B29: =B29 -> 0 | C29: =Base!C29 -> 0 | D29: =B29+C29+2 -> 2 | E29: =ROUNDUP(LOG(D29,2),0) -> 1 | F29: =POWER(2,E29) -> 256 | G29: =32-E29 -> 31 | H29: =MOD(H28+F28,256) -> 0 | I29: =I28+TRUNC((H28+F28)/256) -> 2 | L29: =CONCATENATE("192.168.",I29,".",H29) -> 192.168.2.0 | M29: =VLOOKUP(G29, MaskTable!A:B, 2, FALSE) -> 255.255.255.128 | N29: =CONCATENATE("192.168.",I29,".",H29+1) -> 192.168.2.1 | O29: =IF(C29>0, CONCATENATE("192.168.",I29,".",H29+2), "N/A") -> N/A | P29: =IF(C29>0, CONCATENATE("192.168.",I29,".",H29+1+C29), "N/A") -> N/A | Q29: =CONCATENATE("192.168.",I29,".",IF(C29=0, H29+2, H29+2+C29)) -> 192.168.2.3 | R29: =CONCATENATE("192.168.",I29,".",H29+F29-2) -> 192.168.2.126 | S29: =CONCATENATE("192.168.",I29,".",H29+F29-1) -> 192.168.2.127
A30: =Base!A30 -> Síť 26 | B30: =Base!B30 -> 0 | C30: =Base!C30 -> 0 | D30: =B30+C30+2 -> 2 | E30: =ROUNDUP(LOG(D30,2),0) -> 1 | F30: =POWER(2,E30) -> 2 | G30: =32-E30 -> 31 | H30: =MOD(H29+F29,256) -> 0 | I30: =I29+TRUNC((H29+F29)/256) -> 2 | L30: =CONCATENATE("192.168.",I30,".",H30) -> 192.168.2.0 | M30: =VLOOKUP(G30, MaskTable!A:B, 2, FALSE) -> 255.255.255.254 | N30: =CONCATENATE("192.168.",I30,".",H30+1) -> 192.168.2.1 | O30: =IF(C30>0, CONCATENATE("192.168.",I30,".",H30+2), "N/A") -> N/A | P30: =IF(C30>0, CONCATENATE("192.168.",I30,".",H30+1+C30), "N/A") -> N/A | Q30: =CONCATENATE("192.168.",I30,".",IF(C30=0, H30+2, H30+2+C30)) -> 192.168.2.3 | R30: =CONCATENATE("192.168.",I30,".",H30+F30-2) -> 192.168.2.126 | S30: =CONCATENATE("192.168.",I30,".",H30+F30-1) -> 192.168.2.127
A31: =Base!A31 -> Síť 27 | B31: =Base!B31 -> 0 | C31: =Base!C31 -> 0 | D31: =B31+C31+2 -> 2 | E31: =ROUNDUP(LOG(D31,2),0) -> 1 | F31: =POWER(2,E31) -> 2 | G31: =32-E31 -> 31 | H31: =MOD(H30+F30,256) -> 0 | I31: =I30+TRUNC((H30+F30)/256) -> 2 | L31: =CONCATENATE("192.168.",I31,".",H31) -> 192.168.2.0 | M31: =VLOOKUP(G31, MaskTable!A:B, 2, FALSE) -> 255.255.255.254 | N31: =CONCATENATE("192.168.",I31,".",H31+1) -> 192.168.2.1 | O31: =IF(C31>0, CONCATENATE("192.168.",I31,".",H31+2), "N/A") -> N/A | P31: =IF(C31>0, CONCATENATE("192.168.",I31,".",H31+1+C31), "N/A") -> N/A | Q31: =CONCATENATE("192.168.",I31,".",IF(C31=0, H31+2, H31+2+C31)) -> 192.168.2.3 | R31: =CONCATENATE("192.168.",I31,".",H31+F31-2) -> 192.168.2.126 | S31: =CONCATENATE("192.168.",I31,".",H31+F31-1) -> 192.168.2.127
A32: =Base!A32 -> Síť 28 | B32: =Base!B32 -> 0 | C32: =Base!C32 -> 0 | D32: =B32+C32+2 -> 2 | E32: =ROUNDUP(LOG(D32,2),0) -> 1 | F32: =POWER(2,E32) -> 2 | G32: =32-E32 -> 31 | H32: =MOD(H31+F31,256) -> 0 | I32: =I31+TRUNC((H31+F31)/256) -> 2 | L32: =CONCATENATE("192.168.",I32,".",H32) -> 192.168.2.0 | M32: =VLOOKUP(G32, MaskTable!A:B, 2, FALSE) -> 255.255.255.254 | N32: =CONCATENATE("192.168.",I32,".",H32+1) -> 192.168.2.1 | O32: =IF(C32>0, CONCATENATE("192.168.",I32,".",H32+2), "N/A") -> N/A | P32: =IF(C32>0, CONCATENATE("192.168.",I32,".",H32+1+C32), "N/A") -> N/A | Q32: =CONCATENATE("192.168.",I32,".",IF(C32=0, H32+2, H32+2+C32)) -> 192.168.2.3 | R32: =CONCATENATE("192.168.",I32,".",H32+F32-2) -> 192.168.2.126 | S32: =CONCATENATE("192.168.",I32,".",H32+F32-1) -> 192.168.2.127
A33: =Base!A33 -> Síť 29 | B33: =Base!B33 -> 0 | C33: =Base!C33 -> 0 | D33: =B33+C33+2 -> 2 | E33: =ROUNDUP(LOG(D33,2),0) -> 1 | F33: =POWER(2,E33) -> 2 | G33: =32-E33 -> 31 | H33: =MOD(H32+F32,256) -> 0 | I33: =I32+TRUNC((H32+F32)/256) -> 2 | L33: =CONCATENATE("192.168.",I33,".",H33) -> 192.168.2.0 | M33: =VLOOKUP(G33, MaskTable!A:B, 2, FALSE) -> 255.255.255.254 | N33: =CONCATENATE("192.168.",I33,".",H33+1) -> 192.168.2.1 | O33: =IF(C33>0, CONCATENATE("192.168.",I33,".",H33+2), "N/A") -> N/A | P33: =IF(C33>0, CONCATENATE("192.168.",I33,".",H33+1+C33), "N/A") -> N/A | Q33: =CONCATENATE("192.168.",I33,".",IF(C33=0, H33+2, H33+2+C33)) -> 192.168.2.3 | R33: =CONCATENATE("192.168.",I33,".",H33+F33-2) -> 192.168.2.126 | S33: =CONCATENATE("192.168.",I33,".",H33+F33-1) -> 192.168.2.127
A34: =Base!A34 -> Síť 30 | B34: =Base!B34 -> 0 | C34: =Base!C34 -> 0 | D34: =B34+C34+2 -> 2 | E34: =ROUNDUP(LOG(D34,2),0) -> 1 | F34: =POWER(2,E34) -> 2 | G34: =32-E34 -> 31 | H34: =MOD(H33+F33,256) -> 0 | I34: =I33+TRUNC((H33+F33)/256) -> 2 | L34: =CONCATENATE("192.168.",I34,".",H34) -> 192.168.2.0 | M34: =VLOOKUP(G34, MaskTable!A:B, 2, FALSE) -> 255.255.255.254 | N34: =CONCATENATE("192.168.",I34,".",H34+1) -> 192.168.2.1 | O34: =IF(C34>0, CONCATENATE("192.168.",I34,".",H34+2), "N/A") -> N/A | P34: =IF(C34>0, CONCATENATE("192.168.",I34,".",H34+1+C34), "N/A") -> N/A | Q34: =CONCATENATE("192.168.",I34,".",IF(C34=0, H34+2, H34+2+C34)) -> 192.168.2.3 | R34: =CONCATENATE("192.168.",I34,".",H34+F34-2) -> 192.168.2.126 | S34: =CONCATENATE("192.168.",I34,".",H34+F34-1) -> 192.168.2.127
A35: =Base!A35 -> Síť 31 | B35: =Base!B35 -> 0 | C35: =Base!C35 -> 0 | D35: =B35+C35+2 -> 2 | E35: =ROUNDUP(LOG(D35,2),0) -> 1 | F35: =POWER(2,E35) -> 2 | G35: =32-E35 -> 31 | H35: =MOD(H34+F34,256) -> 0 | I35: =I34+TRUNC((H34+F34)/256) -> 2 | L35: =CONCATENATE("192.168.",I35,".",H35) -> 192.168.2.0 | M35: =VLOOKUP(G35, MaskTable!A:B, 2, FALSE) -> 255.255.255.254 | N35: =CONCATENATE("192.168.",I35,".",H35+1) -> 192.168.2.1 | O35: =IF(C35>0, CONCATENATE("192.168.",I35,".",H35+2), "N/A") -> N/A | P35: =IF(C35>0, CONCATENATE("192.168.",I35,".",H35+1+C35), "N/A") -> N/A | Q35: =CONCATENATE("192.168.",I35,".",IF(C35=0, H35+2, H35+2+C35)) -> 192.168.2.3 | R35: =CONCATENATE("192.168.",I35,".",H35+F35-2) -> 192.168.2.126 | S35: =CONCATENATE("192.168.",I35,".",H35+F35-1) -> 192.168.2.127
A36: =Base!A36 -> Síť 32 | B36: =Base!B36 -> 0 | C36: =Base!C36 -> 0 | D36: =B36+C36+2 -> 2 | E36: =ROUNDUP(LOG(D36,2),0) -> 1 | F36: =POWER(2,E36) -> 2 | G36: =32-E36 -> 31 | H36: =MOD(H35+F35,256) -> 0 | I36: =I35+TRUNC((H35+F35)/256) -> 2 | L36: =CONCATENATE("192.168.",I36,".",H36) -> 192.168.2.0 | M36: =VLOOKUP(G36, MaskTable!A:B, 2, FALSE) -> 255.255.255.254 | N36: =CONCATENATE("192.168.",I36,".",H36+1) -> 192.168.2.1 | O36: =IF(C36>0, CONCATENATE("192.168.",I36,".",H36+2), "N/A") -> N/A | P36: =IF(C36>0, CONCATENATE("192.168.",I36,".",H36+1+C36), "N/A") -> N/A | Q36: =CONCATENATE("192.168.",I36,".",IF(C36=0, H36+2, H36+2+C36)) -> 192.168.2.3 | R36: =CONCATENATE("192.168.",I36,".",H36+F36-2) -> 192.168.2.126 | S36: =CONCATENATE("192.168.",I36,".",H36+F36-1) -> 192.168.2.127
A37: =Base!A37 -> Síť 33 | B37: =Base!B37 -> 0 | C37: =Base!C37 -> 0 | D37: =B37+C37+2 -> 2 | E37: =ROUNDUP(LOG(D37,2),0) -> 1 | F37: =POWER(2,E37) -> 2 | G37: =32-E37 -> 31 | H37: =MOD(H36+F36,256) -> 0 | I37: =I36+TRUNC((H36+F36)/256) -> 2 | L37: =CONCATENATE("192.168.",I37,".",H37) -> 192.168.2.0 | M37: =VLOOKUP(G37, MaskTable!A:B, 2, FALSE) -> 255.255.255.254 | N37: =CONCATENATE("192.168.",I37,".",H37+1) -> 192.168.2.1 | O37: =IF(C37>0, CONCATENATE("192.168.",I37,".",H37+2), "N/A") -> N/A | P37: =IF(C37>0, CONCATENATE("192.168.",I37,".",H37+1+C37), "N/A") -> N/A | Q37: =CONCATENATE("192.168.",I37,".",IF(C37=0, H37+2, H37+2+C37)) -> 192.168.2.3 | R37: =CONCATENATE("192.168.",I37,".",H37+F37-2) -> 192.168.2.126 | S37: =CONCATENATE("192.168.",I37,".",H37+F37-1) -> 192.168.2.127
A38: =Base!A38 -> Síť 34 | B38: =Base!B38 -> 0 | C38: =Base!C38 -> 0 | D38: =B38+C38+2 -> 2 | E38: =ROUNDUP(LOG(D38,2),0) -> 1 | F38: =POWER(2,E38) -> 2 | G38: =32-E38 -> 31 | H38: =MOD(H37+F37,256) -> 0 | I38: =I37+TRUNC((H37+F37)/256) -> 2 | L38: =CONCATENATE("192.168.",I38,".",H38) -> 192.168.2.0 | M38: =VLOOKUP(G38, MaskTable!A:B, 2, FALSE) -> 255.255.255.254 | N38: =CONCATENATE("192.168.",I38,".",H38+1) -> 192.168.2.1 | O38: =IF(C38>0, CONCATENATE("192.168.",I38,".",H38+2), "N/A") -> N/A | P38: =IF(C38>0, CONCATENATE("192.168.",I38,".",H38+1+C38), "N/A") -> N/A | Q38: =CONCATENATE("192.168.",I38,".",IF(C38=0, H38+2, H38+2+C38)) -> 192.168.2.3 | R38: =CONCATENATE("192.168.",I38,".",H38+F38-2) -> 192.168.2.126 | S38: =CONCATENATE("192.168.",I38,".",H38+F38-1) -> 192.168.2.127
A39: =Base!A39 -> Síť 35 | B39: =Base!B39 -> 0 | C39: =Base!C39 -> 0 | D39: =B39+C39+2 -> 2 | E39: =ROUNDUP(LOG(D39,2),0) -> 1 | F39: =POWER(2,E39) -> 2 | G39: =32-E39 -> 31 | H39: =MOD(H38+F38,256) -> 0 | I39: =I38+TRUNC((H38+F38)/256) -> 2 | L39: =CONCATENATE("192.168.",I39,".",H39) -> 192.168.2.0 | M39: =VLOOKUP(G39, MaskTable!A:B, 2, FALSE) -> 255.255.255.254 | N39: =CONCATENATE("192.168.",I39,".",H39+1) -> 192.168.2.1 | O39: =IF(C39>0, CONCATENATE("192.168.",I39,".",H39+2), "N/A") -> N/A | P39: =IF(C39>0, CONCATENATE("192.168.",I39,".",H39+1+C39), "N/A") -> N/A | Q39: =CONCATENATE("192.168.",I39,".",IF(C39=0, H39+2, H39+2+C39)) -> 192.168.2.3 | R39: =CONCATENATE("192.168.",I39,".",H39+F39-2) -> 192.168.2.126 | S39: =CONCATENATE("192.168.",I39,".",H39+F39-1) -> 192.168.2.127
A40: =Base!A40 -> Síť 36 | B40: =Base!B40 -> 0 | C40: =Base!C40 -> 0 | D40: =B40+C40+2 -> 2 | E40: =ROUNDUP(LOG(D40,2),0) -> 1 | F40: =POWER(2,E40) -> 2 | G40: =32-E40 -> 31 | H40: =MOD(H39+F39,256) -> 0 | I40: =I39+TRUNC((H39+F39)/256) -> 2 | L40: =CONCATENATE("192.168.",I40,".",H40) -> 192.168.2.0 | M40: =VLOOKUP(G40, MaskTable!A:B, 2, FALSE) -> 255.255.255.254 | N40: =CONCATENATE("192.168.",I40,".",H40+1) -> 192.168.2.1 | O40: =IF(C40>0, CONCATENATE("192.168.",I40,".",H40+2), "N/A") -> N/A | P40: =IF(C40>0, CONCATENATE("192.168.",I40,".",H40+1+C40), "N/A") -> N/A | Q40: =CONCATENATE("192.168.",I40,".",IF(C40=0, H40+2, H40+2+C40)) -> 192.168.2.3 | R40: =CONCATENATE("192.168.",I40,".",H40+F40-2) -> 192.168.2.126 | S40: =CONCATENATE("192.168.",I40,".",H40+F40-1) -> 192.168.2.127
A41: =Base!A41 -> Síť 37 | B41: =Base!B41 -> 0 | C41: =Base!C41 -> 0 | D41: =B41+C41+2 -> 2 | E41: =ROUNDUP(LOG(D41,2),0) -> 1 | F41: =POWER(2,E41) -> 2 | G41: =32-E41 -> 31 | H41: =MOD(H40+F40,256) -> 0 | I41: =I40+TRUNC((H40+F40)/256) -> 2 | L41: =CONCATENATE("192.168.",I41,".",H41) -> 192.168.2.0 | M41: =VLOOKUP(G41, MaskTable!A:B, 2, FALSE) -> 255.255.255.254 | N41: =CONCATENATE("192.168.",I41,".",H41+1) -> 192.168.2.1 | O41: =IF(C41>0, CONCATENATE("192.168.",I41,".",H41+2), "N/A") -> N/A | P41: =IF(C41>0, CONCATENATE("192.168.",I41,".",H41+1+C41), "N/A") -> N/A | Q41: =CONCATENATE("192.168.",I41,".",IF(C41=0, H41+2, H41+2+C41)) -> 192.168.2.3 | R41: =CONCATENATE("192.168.",I41,".",H41+F41-2) -> 192.168.2.126 | S41: =CONCATENATE("192.168.",I41,".",H41+F41-1) -> 192.168.2.127
...

Sheet MaskTable
A1: Prefix (PR) | B1: Maska podsítě (MA) | C1: Host Bity (h) | D1: Velikost bloku (Adres) | E1: Použitelní hosté (Hosté)
A2: 24 | B2: 255.255.255.0 | C2: 8 | D2: 256 | E2: 254
A3: 25 | B3: 255.255.255.128 | C3: 7 | D3: 128 | E3: 126
A4: 26 | B4: 255.255.255.192 | C4: 6 | D4: 64 | E4: 62
A5: 27 | B5: 255.255.255.224 | C5: 5 | D5: 32 | E5: 30
A6: 28 | B6: 255.255.255.240 | C6: 4 | D6: 16 | E6: 14
A7: 29 | B7: 255.255.255.248 | C7: 3 | D7: 8 | E7: 6
A8: 30 | B8: 255.255.255.252 | C8: 2 | D8: 4 | E8: 2
A9: 31 | B9: 255.255.255.254 | C9: 1 | D9: 2 | E9: 2 (Point-to-Point)
A10: 32 | B10: 255.255.255.255 | C10: 0 | D10: 1 | E10: 1 (Host Route)
